Workbook

Sheet sheet1
A1: MSKU | B1: FNSKU | C1: SKU | D1: SKC | E1: ASIN | F1: 品质 | G1: 状态 | H1: 父ASIN | I1: 标题 | J1: 店铺 | K1: 国家 | L1: 配送方式 | M1: 亚马逊品牌 | N1: 变体属性 | O1: 品名 | P1: 分类 | Q1: 本地品牌 | R1: 商品标签 | S1: 创建时间 | T1: 开售时间
A2: R01500203JBK | B2: B07193Z9X6 | C2: DB-SJ02-2-0000137 | D2: =_xlfn.XLOOKUP(C2,[1]单个产品!$A:$A,[1]单个产品!$F:$F) -> LD-PZ-SM-BZ-02-050 | E2: B07193Z9X6 | F2: =_xlfn.XLOOKUP(C2,[1]单个产品!$A:$A,[1]单个产品!$U:$U) -> 标准 | G2: 在售 | H2: B07JZY66ZK | I2: VATIN 6mm Double Faced Black Polyester Satin Ribbon - 45 Metre for Gift Wrapping Ornaments Party Favor Braids Baby Shower Decoration Floral Arrangement Craft Supplies | J2: VATIN-UK | K2: 英国 | L2: FBA | M2: VATIN | N2: [size:6mm X 45 Metres];[color:Red] | O2: 涤纶带-普通织边-双面织-标准-2分-50码-Black | P2: 丝带\胚染\涤纶带 | R2: 维护 | S2: 2020-04-30 19:03:54 +01:00
A3: RTEST01 | B3: X0016ADFUX | C3: 3DB-SJ02-2-0000151 | D3: =_xlfn.XLOOKUP(C3,[1]单个产品!$A:$A,[1]单个产品!$F:$F) -> #N/A | E3: B07RPF74TF | F3: =_xlfn.XLOOKUP(C3,[1]单个产品!$A:$A,[1]单个产品!$U:$U) -> #N/A | G3: 在售 | H3: B07JZY66ZK | I3: VATIN Solid Color Double Faced Polyester Satin Ribbon 10 Colors 10mm X 4.5m Each Total 45 Metre Per Package Ribbon Set, Perfect for Gift Wrapping, Hair Bow, Trimming, Sewing and Other Craft Projects | J3: VATIN-UK | K3: 英国 | L3: FBA | M3: VATIN | N3: [size:10mm X 45 Metres];[color:Set #7] | O3: 涤纶带-双面-不带边-标准-3分-5Y-10卷-Mix Color | P3: 丝带\胚染\涤纶带 | R3: 维护,战略 | S3: 2020-04-28 07:04:26 +01:00
A4: 3DB-SJ02-2-0001502 | B4: X0025ZGZYB | C4: 3DB-SJ02-2-0001502 | D4: =_xlfn.XLOOKUP(C4,[1]单个产品!$A:$A,[1]单个产品!$F:$F) -> LD-PZ-SM-BZ-02-050 | E4: B0D7PZJCQV | F4: =_xlfn.XLOOKUP(C4,[1]单个产品!$A:$A,[1]单个产品!$U:$U) -> 标准 | G4: 停售 | H4: B07JZY66ZK | I4: VATIN Double Face Ivory Satin Ribbon 1/4" Continuous 50 Yards,Ivory Polyester Fabric Ribbon use for Bows Bouquet, Gift Wrapping, Floral Arrangement Wedding Decoration | J4: VATIN-UK | K4: 英国 | L4: FBA | M4: VATIN | N4: [size:1/4" X 50 Yards];[color:Ivory] | O4: 涤纶带-普通织边-双面织-标准-2分-50码-Ivory | P4: 丝带\胚染\涤纶带 | R4: 新变体 | S4: 2024-11-01 01:40:48 +00:00
A5: R01500202JWT | B5: B0716JJ5J1 | C5: DB-SJ08-0-0000122 | D5: =_xlfn.XLOOKUP(C5,[1]单个产品!$A:$A,[1]单个产品!$F:$F) -> DL-LW-PZ-BZ-02-050 | E5: B0716JJ5J1 | F5: =_xlfn.XLOOKUP(C5,[1]单个产品!$A:$A,[1]单个产品!$U:$U) -> 标准 | G5: 在售 | H5: B08F9SSDKB | I5: VATIN Solid 6mm X 45 Metres White Grosgrain Ribbon 23 Metres Each Roll Perfect for Crafts, Wedding Decor, DIY Hair Accessories, Sewing, Gift Package Wrapping and More | J5: VATIN-UK | K5: 英国 | L5: FBA | M5: VATIN | N5: [size:6 mm X 45 Metre];[color:White] | O5: 涤纶-罗纹带-普通织边-标准-2分-50码-White | P5: 丝带\胚染\罗纹带 | R5: 维护 | S5: 2020-04-30 16:04:50 +01:00
A6: DB-SJ02-2-0000148 | B6: X0016DNX11 | C6: DB-SJ02-2-0000148 | D6: =_xlfn.XLOOKUP(C6,[1]单个产品!$A:$A,[1]单个产品!$F:$F) -> LD-PZ-SM-BZ-05-025 | E6: B07RS49ZDV | F6: =_xlfn.XLOOKUP(C6,[1]单个产品!$A:$A,[1]单个产品!$U:$U) -> 标准 | G6: 在售 | H6: B07JZY66ZK | I6: VATIN 16mm Double Faced Polyester Deep Navy Blue Satin Ribbon - 23 Metre Spool, Perfect for Wedding Decor, Wreath, Baby Shower,Gift Package Wrapping and Other Projects | J6: VATIN-UK | K6: 英国 | L6: FBA | M6: VATIN | N6: [size:16mm X 23 Metres];[color:Deep Navy] | O6: 涤纶带-普通织边-双面织-标准-5分-25码-Dk.Navy | P6: 丝带\胚染\涤纶带 | R6: 维护 | S6: 2020-04-28 07:04:26 +01:00
A7: 3DB-SJ02-2-0000282 | B7: X0016BDN1X | C7: 3DB-SJ02-2-0000282 | D7: =_xlfn.XLOOKUP(C7,[1]单个产品!$A:$A,[1]单个产品!$F:$F) -> LD-PZ-SM-BZ-07-025 | E7: B086C7B3FW | F7: =_xlfn.XLOOKUP(C7,[1]单个产品!$A:$A,[1]单个产品!$U:$U) -> 标准 | G7: 在售 | H7: B07JZY66ZK | I7: VATIN 22mm Double Faced Polyester Satin Ribbon Wine - 23 Metre/Spool, Perfect for Wedding Decor, Wreath, Baby Shower,Gift Package Wrapping and Other Projects | J7: VATIN-UK | K7: 英国 | L7: FBA | M7: VATIN | N7: [size:22mm X 23 Metres];[color:Wine] | O7: 涤纶带-普通织边-双面织-标准-7分-25码-Wine | P7: 丝带\胚染\涤纶带 | R7: 维护 | S7: 2020-04-30 08:54:51 +01:00
A8: R01500303JWT | B8: B0722PS3XT | C8: DB-SJ02-2-0000121 | D8: =_xlfn.XLOOKUP(C8,[1]单个产品!$A:$A,[1]单个产品!$F:$F) -> LD-PZ-SM-BZ-03-050 | E8: B0722PS3XT | F8: =_xlfn.XLOOKUP(C8,[1]单个产品!$A:$A,[1]单个产品!$U:$U) -> 标准 | G8: 停售 | H8: B07JZY66ZK | I8: VATIN 10mm Double Faced White Polyester Satin Ribbon - 45 Metre for Gift Wrapping Ornaments Party Favor Braids Baby Shower Decoration Floral Arrangement Craft Supplies | J8: VATIN-UK | K8: 英国 | L8: FBA | M8: VATIN | N8: [size:10mm X 45 Metres];[color:White] | O8: 涤纶带-普通织边-双面织-标准-3分-50码-White | P8: 丝带\胚染\涤纶带 | R8: 维护 | S8: 2020-04-30 10:03:09 +01:00
A9: R04250803JBK | B9: X0016BF01T | C9: DB-SJ02-2-0000140 | D9: =_xlfn.XLOOKUP(C9,[1]单个产品!$A:$A,[1]单个产品!$F:$F) -> LD-PZ-SM-BZ-08-025 | E9: B079K8CB4P | F9: =_xlfn.XLOOKUP(C9,[1]单个产品!$A:$A,[1]单个产品!$U:$U) -> 标准 | G9: 在售 | H9: B07JZY66ZK | I9: VATIN 25mm Double Faced Polyester Satin Ribbon Black - 23 Metre/Spool, Perfect for Wedding, Wreath, Baby Shower,Packing and Other Projects. | J9: VATIN-UK | K9: 英国 | L9: FBA | M9: VATIN | N9: [size:25mm X 23 Metres];[color:Black] | O9: 涤纶带-普通织边-双面织-标准-8分-25码-Black | P9: 丝带\胚染\涤纶带 | R9: 维护 | S9: 2020-04-30 10:39:35 +01:00
A10: R04250803JNB | B10: X0016DM0P1 | C10: DB-SJ02-2-0000112 | D10: =_xlfn.XLOOKUP(C10,[1]单个产品!$A:$A,[1]单个产品!$F:$F) -> LD-PZ-SM-BZ-08-025 | E10: B079K8Q5V3 | F10: =_xlfn.XLOOKUP(C10,[1]单个产品!$A:$A,[1]单个产品!$U:$U) -> 标准 | G10: 在售 | H10: B07JZY66ZK | I10: VATIN 25mm Double Faced Polyester Satin Ribbon Deep Navy Blue - 23 Metre/Spool, Perfect for Wedding, Wreath, Baby Shower,Packing and Other Projects. | J10: VATIN-UK | K10: 英国 | L10: FBA | M10: VATIN | N10: [size:25mm X 23 Metres];[color:Deep Navy] | O10: 涤纶带-普通织边-双面织-标准-8分-25码-Dk.Navy | P10: 丝带\胚染\涤纶带 | R10: 维护 | S10: 2020-04-30 10:39:35 +01:00
A11: R04100305JBK | B11: X0016AKW6N | C11: DB-SJ09-1-0000001 | D11: =_xlfn.XLOOKUP(C11,[1]单个产品!$A:$A,[1]单个产品!$F:$F) -> NL-SR-PZ-DM-BZ-03-010 | E11: B079K8S2J6 | F11: =_xlfn.XLOOKUP(C11,[1]单个产品!$A:$A,[1]单个产品!$U:$U) -> 标准 | G11: 在售 | H11: B0DFLS549K | I11: VATIN 10mm Wide Crushed Velvet Ribbons by Yards Spool, Black,Perfect use for Choker. | J11: VATIN-UK | K11: 英国 | L11: FBA | M11: VATIN | N11: [size:10MM];[color:Black] | O11: 尼龙-丝绒带-普通织边-单面织-标准-3分-10码-Black | P11: 丝带\胚染\丝绒带 | R11: 维护,Q1,Q4 | S11: 2020-04-28 15:37:12 +01:00
A12: DB-SJ02-2-0000150 | B12: X0016ADFVH | C12: DB-SJ02-2-0000150 | D12: =_xlfn.XLOOKUP(C12,[1]单个产品!$A:$A,[1]单个产品!$F:$F) -> LD-PZ-SM-BZ-05-025 | E12: B07RWMSXSG | F12: =_xlfn.XLOOKUP(C12,[1]单个产品!$A:$A,[1]单个产品!$U:$U) -> 标准 | G12: 在售 | H12: B07JZY66ZK | I12: VATIN 16mm Double Faced Polyester Black Satin Ribbon - 23 Metre Spool, Perfect for Wedding Decor, Wreath, Baby Shower, Bridal Shower, Hair Bow, Gift Package Wrapping & Other Projects | J12: VATIN-UK | K12: 英国 | L12: FBA | M12: VATIN | N12: [size:16mm X 23 Metres];[color:Black] | O12: 涤纶带-普通织边-双面织-标准-5分-25码-Black | P12: 丝带\胚染\涤纶带 | R12: 维护 | S12: 2020-04-28 07:04:26 +01:00
A13: DB-SJ02-2-0000143-N | B13: X0016AAYRF | C13: DB-SJ02-2-0000143 | D13: =_xlfn.XLOOKUP(C13,[1]单个产品!$A:$A,[1]单个产品!$F:$F) -> LD-PZ-SM-BZ-05-025 | E13: B07RWV8DBY | F13: =_xlfn.XLOOKUP(C13,[1]单个产品!$A:$A,[1]单个产品!$U:$U) -> 标准 | G13: 在售 | H13: B07JZY66ZK | I13: VATIN 16mm Double Faced Polyester White Satin Ribbon - 23 Metre Spool, Perfect for Wedding Decor, Wreath, Baby Shower,Gift Package Wrapping and Other Projects | J13: VATIN-UK | K13: 英国 | L13: FBA | M13: VATIN | N13: [size:16mm X 23 Metres];[color:White] | O13: 涤纶带-普通织边-双面织-标准-5分-25码-White | P13: 丝带\胚染\涤纶带 | R13: 维护 | S13: 2020-04-28 07:04:26 +01:00
... A26: 3DB-SJ02-2-0000194 | B26: X0016A67IZ | C26: 3DB-SJ02-2-0000194 | D26: =_xlfn.XLOOKUP(C26,[1]单个产品!$A:$A,[1]单个产品!$F:$F) -> LD-PZ-SM-BZ-02-050 | E26: B07TQ78BHR | F26: =_xlfn.XLOOKUP(C26,[1]单个产品!$A:$A,[1]单个产品!$U:$U) -> 标准 | G26: 在售 | H26: B07JZY66ZK | I26: VATIN 6mm Double Faced Autumn Orange Polyester Satin Ribbon - 45 Metre for Gift Wrapping Ornaments Party Favor Braids Baby Shower Decoration Floral Arrangement Craft Supplies | J26: VATIN-UK | K26: 英国 | L26: FBA | M26: VATIN | N26: [size:6mm X 45 Metres];[color:Autumn Orange] | O26: 涤纶带-普通织边-双面织-标准-2分-50码-Autumn Orange | P26: 丝带\胚染\涤纶带 | R26: 新变体 | S26: 2020-04-28 07:04:26 +01:00
A27: R01500203JWT | B27: B07259J6HH | C27: DB-SJ02-2-0000109 | D27: =_xlfn.XLOOKUP(C27,[1]单个产品!$A:$A,[1]单个产品!$F:$F) -> LD-PZ-SM-BZ-02-050 | E27: B07259J6HH | F27: =_xlfn.XLOOKUP(C27,[1]单个产品!$A:$A,[1]单个产品!$U:$U) -> 标准 | G27: 在售 | H27: B07259J6HH | I27: VATIN 6mm Double Faced White Polyester Satin Ribbon - 45 Metre for Gift Wrapping Ornaments Party Favor Braids Baby Shower Decoration Floral Arrangement Craft Supplies | J27: VATIN-UK | K27: 英国 | L27: FBA | M27: VATIN | O27: 涤纶带-普通织边-双面织-标准-2分-50码-White | P27: 丝带\胚染\涤纶带 | R27: 维护,战略 | S27: 2020-05-04 10:45:25 +01:00
A28: 3DB-SJ02-2-0000229 | B28: X0016AE0VB | C28: 3DB-SJ02-2-0000229 | D28: =_xlfn.XLOOKUP(C28,[1]单个产品!$A:$A,[1]单个产品!$F:$F) -> LD-PZ-SM-BZ-16-025 | E28: B0836LD13H | F28: =_xlfn.XLOOKUP(C28,[1]单个产品!$A:$A,[1]单个产品!$U:$U) -> 标准 | G28: 在售 | H28: B07JZY66ZK | I28: VATIN 50mm Solid Black Double Faced Polyester Satin Ribbon for Craft, Gift Wrapping, Hair Bow, Wedding Deco 23 Metre/Spool | J28: VATIN-UK | K28: 英国 | L28: FBA | M28: VATIN | N28: [size:50mm X 23 Metres];[color:Black] | O28: 涤纶带-普通织边-双面织-标准-16分-25码-Black | P28: 丝带\胚染\涤纶带 | R28: 维护 | S28: 2020-04-28 07:04:26 +01:00
A29: 3DB-SJ02-2-0000159 | B29: X0016BAP7D | C29: 3DB-SJ02-2-0000159 | D29: =_xlfn.XLOOKUP(C29,[1]单个产品!$A:$A,[1]单个产品!$F:$F) -> LD-PZ-SM-BZ-08-025 | E29: B07TLYJ212 | F29: =_xlfn.XLOOKUP(C29,[1]单个产品!$A:$A,[1]单个产品!$U:$U) -> 标准 | G29: 在售 | H29: B07JZY66ZK | I29: VATIN 25mm Double Faced Polyester Satin Ribbon Wine - 23 Metre/Spool, Perfect for Wedding, Wreath, Baby Shower,Packing and Other Projects | J29: VATIN-UK | K29: 英国 | L29: FBA | M29: VATIN | N29: [size:25mm X 23 Metres];[color:Wine] | O29: 涤纶带-普通织边-双面织-标准-8分-25码-Wine | P29: 丝带\胚染\涤纶带 | R29: 维护 | S29: 2020-04-30 10:39:35 +01:00
A30: 3DB-SJ01-1-0000080 | B30: X001QEVXL7 | C30: 3DB-SJ01-1-0000080 | D30: =_xlfn.XLOOKUP(C30,[1]单个产品!$A:$A,[1]单个产品!$F:$F) -> DL-DD-PZ-DM-BZ-12-025 | E30: B0BX9Q4JNV | F30: =_xlfn.XLOOKUP(C30,[1]单个产品!$A:$A,[1]单个产品!$U:$U) -> 标准 | G30: 停售 | H30: B0BX9G9V6V | I30: VATIN Dark Green Satin Ribbon Polyester 40mm X 23m(25 Yards) Craft Fabric Ribbon Perfect for Gift Wrapping, Hair Bow,Party Balloon Trimming, Cake Decoration Sewing and Other Craft Projects | J30: VATIN-UK | K30: 英国 | L30: FBA | M30: VATIN | N30: [size:40mm X 23 Meters];[color:Dark green] | O30: 涤纶-缎带-普通织边-单面织-标准-12分-25码-Dk.Green | P30: 丝带\胚染\缎带 | R30: 维护 | S30: 2023-03-03 02:01:37 +00:00
A31: 3DB-SJ08-0-0001057 | B31: X0025IP8HD | C31: 3DB-SJ08-0-0001057 | D31: =_xlfn.XLOOKUP(C31,[1]单个产品!$A:$A,[1]单个产品!$F:$F) -> DL-LW-PZ-BZ-03-050 | E31: B0DJGBZSDL | F31: =_xlfn.XLOOKUP(C31,[1]单个产品!$A:$A,[1]单个产品!$U:$U) -> 标准 | G31: 在售 | H31: B0DJGBZSDL | I31: VATIN Solid 10 mm X 45 Metres Royal Blue Grosgrain Ribbon 45 Metres Each Roll Perfect for Crafts, Wedding Decor, DIY Hair Accessories, Sewing, Gift Package Wrapping and More | J31: VATIN-UK | K31: 英国 | L31: FBA | M31: VATIN | O31: 涤纶-罗纹带-普通织边-标准-3分-50码-Royal | P31: 丝带\胚染\罗纹带 | R31: 维护 | S31: 2024-10-14 04:01:20 +01:00
A32: 3DB-SJ08-0-0001063 | B32: X0025IQK6L | C32: 3DB-SJ08-0-0001063 | D32: =_xlfn.XLOOKUP(C32,[1]单个产品!$A:$A,[1]单个产品!$F:$F) -> DL-LW-PZ-BZ-03-050 | E32: B0DJGB7WSB | F32: =_xlfn.XLOOKUP(C32,[1]单个产品!$A:$A,[1]单个产品!$U:$U) -> 标准 | G32: 在售 | H32: B08F9SSDKB | I32: VATIN Solid 10 mm X 45 Metres Orange Grosgrain Ribbon 45 Metres Each Roll Perfect for Crafts, Wedding Decor, DIY Hair Accessories, Sewing, Gift Package Wrapping and More | J32: VATIN-UK | K32: 英国 | L32: FBA | M32: VATIN | N32: [size:10 mm X 45 Metre];[color:Orange] | O32: 涤纶-罗纹带-普通织边-标准-3分-50码-Orange | P32: 丝带\胚染\罗纹带 | R32: 维护 | S32: 2024-10-14 04:01:20 +01:00
A33: 3DB-SJ14-0-0000616 | B33: X001SDDYU9 | C33: 3DB-SJ14-0-0000616 | D33: =_xlfn.XLOOKUP(C33,[1]单个产品!$A:$A,[1]单个产品!$F:$F) -> LD-SZ-SM-BZ-03-050 | E33: B0BRSGQCYJ | F33: =_xlfn.XLOOKUP(C33,[1]单个产品!$A:$A,[1]单个产品!$U:$U) -> 标准 | G33: 在售 | H33: B0CDRRTTHC | I33: VATIN Double Faced Satin Ribbon 10mm Emerald Green with Gold Edge Continuous 45 Metre for Decoration, Craft, Gift Wrappping Wedding Card Decoration | J33: VATIN-UK | K33: 英国 | L33: FBA | M33: VATIN | N33: [size:10mm X 45 Metres];[color:Emerald Green] | O33: 涤纶带-特殊织边-双面织-标准-3分-50码-Emerald & Gold | P33: 丝带\胚染\涤纶带 | S33: 2023-05-26 06:10:41 +01:00
A34: 3DB-SJ01-1-0000072 | B34: X001QEVXKX | C34: 3DB-SJ01-1-0000072 | D34: =_xlfn.XLOOKUP(C34,[1]单个产品!$A:$A,[1]单个产品!$F:$F) -> DL-DD-PZ-DM-BZ-12-025 | E34: B0BX9P7GL2 | F34: =_xlfn.XLOOKUP(C34,[1]单个产品!$A:$A,[1]单个产品!$U:$U) -> 标准 | G34: 在售 | H34: B0BX9G9V6V | I34: VATIN White Satin Ribbon Polyester 40mm X 23m(25 Yards) Craft Fabric Ribbon Perfect for Gift Wrapping,Hair Bow,Party Balloon Trimming, Cake Decoration Sewing and Other Craft Projects | J34: VATIN-UK | K34: 英国 | L34: FBA | M34: VATIN | N34: [size:40mm X 23 Meters];[color:White] | O34: 涤纶-缎带-普通织边-单面织-标准-12分-25码-White | P34: 丝带\胚染\缎带 | R34: 维护 | S34: 2023-03-03 02:01:37 +00:00
A35: 3DB-SJ14-1-0000015 | B35: X001US2O2B | C35: 3DB-SJ14-1-0000015 | D35: =_xlfn.XLOOKUP(C35,[1]单个产品!$A:$A,[1]单个产品!$F:$F) -> DL-RM-QB-BZ-32-022 | E35: B0BZHP9RNC | F35: =_xlfn.XLOOKUP(C35,[1]单个产品!$A:$A,[1]单个产品!$U:$U) -> 标准 | G35: 在售 | H35: B0CDP5VZ69 | I35: VATIN 4 Inch x 22 Yards Wide Red Satin Solid Ribbon for Grand Opening, Ceremony, Party, Festival Decoration | J35: VATIN-UK | K35: 英国 | L35: FBA | M35: VATIN | N35: [size:4" x 22 Yard];[color:Red] | O35: 涤纶-缎面布-切边-标准-32分-22码-Red | P35: 丝带\布料加工\涤纶布 | S35: 2023-08-29 14:14:47 +01:00
A36: 3DB-SJ02-2-0000285 | B36: X0016BDN27 | C36: 3DB-SJ02-2-0000285 | D36: =_xlfn.XLOOKUP(C36,[1]单个产品!$A:$A,[1]单个产品!$F:$F) -> LD-PZ-SM-BZ-07-025 | E36: B086C65FWL | F36: =_xlfn.XLOOKUP(C36,[1]单个产品!$A:$A,[1]单个产品!$U:$U) -> 标准 | G36: 在售 | H36: B07JZY66ZK | I36: VATIN 22mm Double Faced Polyester Satin Ribbon Sideshow Rose - 23 Metre/Spool, Perfect for Wedding Decor, Wreath, Baby Shower,Gift Package Wrapping and Other Projects | J36: VATIN-UK | K36: 英国 | L36: FBA | M36: VATIN | N36: [size:22mm X 23 Metres];[color:Sideshow Rose] | O36: 涤纶带-普通织边-双面织-标准-7分-25码-Sideshow Rose | P36: 丝带\胚染\涤纶带 | R36: 维护 | S36: 2020-04-30 08:54:51 +01:00
A37: 3DB-SJ02-2-0000178 | B37: X0016ADFU3 | C37: 3DB-SJ02-2-0000178 | D37: =_xlfn.XLOOKUP(C37,[1]单个产品!$A:$A,[1]单个产品!$F:$F) -> LD-PZ-SM-BZ-02-050 | E37: B07TM2B9GJ | F37: =_xlfn.XLOOKUP(C37,[1]单个产品!$A:$A,[1]单个产品!$U:$U) -> 标准 | G37: 在售 | H37: B07JZY66ZK | I37: VATIN 6mm inches Double Faced Light Pink/Baby Pink Polyester Satin Ribbon - 45 Metre for Gift Wrapping Ornaments Party Favor Braids Baby Shower Decoration Floral Arrangement Craft Supplies | J37: VATIN-UK | K37: 英国 | L37: FBA | M37: VATIN | N37: [size:6mm X 45 Metres];[color:Light Pink] | O37: 涤纶带-普通织边-双面织-标准-2分-50码-Lt.Pink | P37: 丝带\胚染\涤纶带 | R37: 维护 | S37: 2020-04-28 07:04:26 +01:00
A38: R04251602JWT | B38: X0016C8URT | C38: DB-SJ08-0-0000278 | D38: =_xlfn.XLOOKUP(C38,[1]单个产品!$A:$A,[1]单个产品!$F:$F) -> DL-LW-PZ-BZ-16-025 | E38: B079K86991 | F38: =_xlfn.XLOOKUP(C38,[1]单个产品!$A:$A,[1]单个产品!$U:$U) -> 标准 | G38: 在售 | H38: B08F9SSDKB | I38: VATIN 50mm Solid White Grosgrain Ribbon Spool -23 Metre, Great for Sewing, Gift Wrapping, Hair Bows, Flower Arranging, Home Decorating | J38: VATIN-UK | K38: 英国 | L38: FBA | M38: VATIN | N38: [size:50 mm X 23 Metre];[color:White] | O38: 涤纶-罗纹带-普通织边-标准-16分-25码-White | P38: 丝带\胚染\罗纹带 | R38: 维护 | S38: 2020-05-04 10:34:26 +01:00
A39: R01500302JRD | B39: B0727W5DGD | C39: 3DB-SJ08-0-0000310 | D39: =_xlfn.XLOOKUP(C39,[1]单个产品!$A:$A,[1]单个产品!$F:$F) -> DL-LW-PZ-BZ-03-050 | E39: B0727W5DGD | F39: =_xlfn.XLOOKUP(C39,[1]单个产品!$A:$A,[1]单个产品!$U:$U) -> 标准 | G39: 在售 | H39: B08F9SSDKB | I39: VATIN Solid 10mm X 45 Metres Red Grosgrain Ribbon 23 Metres Each Roll Perfect for Crafts, Wedding Decor, DIY Hair Accessories, Sewing, Gift Package Wrapping and More | J39: VATIN-UK | K39: 英国 | L39: FBA | M39: VATIN | N39: [size:10 mm X 45 Metre];[color:Red] | O39: 涤纶-罗纹带-普通织边-标准-3分-50码-Red | P39: 丝带\胚染\罗纹带 | R39: 维护 | S39: 2020-05-04 11:05:22 +01:00
A40: 3DB-SJ01-1-0000045 | B40: X001QEVXI5 | C40: 3DB-SJ01-1-0000045 | D40: =_xlfn.XLOOKUP(C40,[1]单个产品!$A:$A,[1]单个产品!$F:$F) -> DL-DD-PZ-DM-BZ-03-025 | E40: B0BX9LVV9X | F40: =_xlfn.XLOOKUP(C40,[1]单个产品!$A:$A,[1]单个产品!$U:$U) -> 标准 | G40: 在售 | H40: B0BX9G9V6V | I40: VATIN Black Satin Ribbon Polyester 10mm X 23m(25 Yards) Craft Fabric Ribbon Perfect for Gift Wrapping,Hair Bow,Party Balloon Trimming, Cake Decoration Sewing and Other Craft Projects | J40: VATIN-UK | K40: 英国 | L40: FBA | M40: VATIN | N40: [size:10mm X 23 Meters];[color:Black] | O40: 涤纶-缎带-普通织边-单面织-标准-3分-25码-Black | P40: 丝带\胚染\缎带 | R40: 维护 | S40: 2023-03-03 02:01:37 +00:00
A41: R01500202JRYB | B41: B0716JJ7JZ | C41: DB-SJ08-0-0000119 | D41: =_xlfn.XLOOKUP(C41,[1]单个产品!$A:$A,[1]单个产品!$F:$F) -> DL-LW-PZ-BZ-02-050 | E41: B0716JJ7JZ | F41: =_xlfn.XLOOKUP(C41,[1]单个产品!$A:$A,[1]单个产品!$U:$U) -> 标准 | G41: 在售 | H41: B08F9SSDKB | I41: VATIN Solid 6mm X 45 Metres Navy Blue Grosgrain Ribbon 23 Metres Each Roll Perfect for Crafts, Wedding Decor, DIY Hair Accessories, Sewing, Gift Package Wrapping and More | J41: VATIN-UK | K41: 英国 | L41: FBA | M41: VATIN | N41: [size:6 mm X 45 Metre];[color:Navy Blue] | O41: 涤纶-罗纹带-普通织边-标准-2分-50码-Dk.Marine | P41: 丝带\胚染\罗纹带 | R41: 维护 | S41: 2020-05-04 10:59:20 +01:00
A42: 3DB-SJ02-2-0000260 | B42: X0016BCT9P | C42: 3DB-SJ02-2-0000260 | D42: =_xlfn.XLOOKUP(C42,[1]单个产品!$A:$A,[1]单个产品!$F:$F) -> LD-PZ-SM-BZ-05-025 | E42: B083R4F6N4 | F42: =_xlfn.XLOOKUP(C42,[1]单个产品!$A:$A,[1]单个产品!$U:$U) -> 标准 | G42: 停售 | H42: B07JZY66ZK | I42: VATIN 16mm Double Faced Polyester Wine Satin Ribbon - 23 Metre Spool, Perfect for Wedding Decor, Wreath, Baby Shower,Gift Package Wrapping and Other Projects | J42: VATIN-UK | K42: 英国 | L42: FBA | M42: VATIN | N42: [size:16mm X 23 Metres];[color:Wine] | O42: 涤纶带-普通织边-双面织-标准-5分-25码-Wine | P42: 丝带\胚染\涤纶带 | R42: 维护 | S42: 2020-04-30 09:50:12 +01:00
A43: 3DB-SJ08-0-0001115 | B43: X0025IOG6H | C43: 3DB-SJ08-0-0001115 | D43: =_xlfn.XLOOKUP(C43,[1]单个产品!$A:$A,[1]单个产品!$F:$F) -> DL-LW-PZ-BZ-12-025 | E43: B0DJGD8NRX | F43: =_xlfn.XLOOKUP(C43,[1]单个产品!$A:$A,[1]单个产品!$U:$U) -> 标准 | G43: 在售 | H43: B08F9SSDKB | I43: VATIN 38 mm Solid Forest Green Grosgrain Ribbon Spool -23 Metres, Great for Sewing, Gift Wrapping, Hair Bows, Flower Arranging, Home Decorating | J43: VATIN-UK | K43: 英国 | L43: FBA | M43: VATIN | N43: [size:38 mmX 23 Metre];[color:Forest Green] | O43: 涤纶-罗纹带-普通织边-标准-12分-25码-Forest | P43: 丝带\胚染\罗纹带 | R43: 维护 | S43: 2024-10-14 04:01:20 +01:00
A44: 3DB-SJ02-2-0000254 | B44: X0016A67RL | C44: 3DB-SJ02-2-0000254 | D44: =_xlfn.XLOOKUP(C44,[1]单个产品!$A:$A,[1]单个产品!$F:$F) -> LD-PZ-SM-BZ-12-025 | E44: B0836CVNXF | F44: =_xlfn.XLOOKUP(C44,[1]单个产品!$A:$A,[1]单个产品!$U:$U) -> 标准 | G44: 在售 | H44: B07JZY66ZK | I44: VATIN 38mm Wide Double Faced Polyester Sideshow Rose Satin Ribbon Continuous Ribbon- 23 Metre, Perfect for Wedding, Gift Wrapping, Bow Making& Other Projects | J44: VATIN-UK | K44: 英国 | L44: FBA | M44: VATIN | N44: [size:38mm X 23 Metres];[color:Sideshow Rose] | O44: 涤纶带-普通织边-双面织-标准-12分-25码-Sideshow Rose | P44: 丝带\胚染\涤纶带 | R44: 维护 | S44: 2020-04-28 07:04:26 +01:00
A45: R04250803JWT | B45: X0016BBLCB | C45: DB-SJ02-2-0000127 | D45: =_xlfn.XLOOKUP(C45,[1]单个产品!$A:$A,[1]单个产品!$F:$F) -> LD-PZ-SM-BZ-08-025 | E45: B079K9CGCV | F45: =_xlfn.XLOOKUP(C45,[1]单个产品!$A:$A,[1]单个产品!$U:$U) -> 标准 | G45: 在售 | H45: B07JZY66ZK | I45: VATIN 25mm Double Faced Polyester Satin Ribbon White - 23 Metre/Spool, Perfect for Wedding, Wreath, Baby Shower,Packing and Other Projects. | J45: VATIN-UK | K45: 英国 | L45: FBA | M45: VATIN | N45: [size:25mm X 23 Metres];[color:White] | O45: 涤纶带-普通织边-双面织-标准-8分-25码-White | P45: 丝带\胚染\涤纶带 | R45: 维护 | S45: 2020-04-30 10:39:35 +01:00
A46: R01500302JBK | B46: B071L1HK76 | C46: DB-SJ08-0-0000285 | D46: =_xlfn.XLOOKUP(C46,[1]单个产品!$A:$A,[1]单个产品!$F:$F) -> DL-LW-PZ-BZ-03-050 | E46: B071L1HK76 | F46: =_xlfn.XLOOKUP(C46,[1]单个产品!$A:$A,[1]单个产品!$U:$U) -> 标准 | G46: 在售 | H46: B08F9SSDKB | I46: VATIN Solid 10mm X 45 Metres Black Grosgrain Ribbon 23 Metres Each Roll Perfect for Crafts, Wedding Decor, DIY Hair Accessories, Sewing, Gift Package Wrapping and More | J46: VATIN-UK | K46: 英国 | L46: FBA | M46: VATIN | N46: [size:10 mm X 45 Metre];[color:Black] | O46: 涤纶-罗纹带-普通织边-标准-3分-50码-Black | P46: 丝带\胚染\罗纹带 | R46: 维护,战略 | S46: 2020-04-29 18:30:28 +01:00
A47: R01500202JBK | B47: B071L1H5X8 | C47: DB-SJ08-0-0000284 | D47: =_xlfn.XLOOKUP(C47,[1]单个产品!$A:$A,[1]单个产品!$F:$F) -> DL-LW-PZ-BZ-02-050 | E47: B071L1H5X8 | F47: =_xlfn.XLOOKUP(C47,[1]单个产品!$A:$A,[1]单个产品!$U:$U) -> 标准 | G47: 在售 | H47: B08F9SSDKB | I47: VATIN Solid 6mm X 45 Metres Black Grosgrain Ribbon 23 Metres Each Roll Perfect for Crafts, Wedding Decor, DIY Hair Accessories, Sewing, Gift Package Wrapping and More | J47: VATIN-UK | K47: 英国 | L47: FBA | M47: VATIN | N47: [size:6 mm X 45 Metre];[color:Black] | O47: 涤纶-罗纹带-普通织边-标准-2分-50码-Black | P47: 丝带\胚染\罗纹带 | R47: 维护 | S47: 2020-04-30 19:03:54 +01:00
... A115: 3DB-SJ09-1-0000332 | B115: X0023K7HYF | C115: 3DB-SJ09-1-0000332 | D115: =_xlfn.XLOOKUP(C115,[1]单个产品!$A:$A,[1]单个产品!$F:$F) -> NL-SR-PZ-DM-BZ-08-025 | E115: B0D5458GQB | F115: =_xlfn.XLOOKUP(C115,[1]单个产品!$A:$A,[1]单个产品!$U:$U) -> 标准 | G115: 在售 | H115: B08B5YK3K2 | I115: VATIN 26mm Wide Nylon Woven Vintage Olive Velvet Ribbons by 23 Metres Spool, Perfect use for Choker, Gift Wrapping, Floral Bouquets, Home Décor | J115: VATIN-UK | K115: 英国 | L115: FBA | M115: VATIN | N115: [size:26mm];[color:Olive] | O115: 尼龙-丝绒带-普通织边-单面织-标准-8分-25码-Olive | P115: 丝带\胚染\丝绒带 | R115: 维护,Q4,Q1 | S115: 2024-08-07 08:55:19 +01:00
A116: 3DB-SJ14-1-0000076 | B116: X0020WNE93 | C116: 3DB-SJ14-1-0000076 | D116: =_xlfn.XLOOKUP(C116,[1]单个产品!$A:$A,[1]单个产品!$F:$F) -> DL-RM-QB-BZ-64-022 | E116: B0CR41RKCK | F116: =_xlfn.XLOOKUP(C116,[1]单个产品!$A:$A,[1]单个产品!$U:$U) -> 标准 | G116: 在售 | H116: B0CDP5VZ69 | I116: VATIN 8 Inch x 22 Yards Wide Red Satin Solid Ribbon for Grand Opening & Wedding Decoration Kit | J116: VATIN-UK | K116: 英国 | L116: FBA | M116: VATIN | N116: [size:8" x 22 Yard];[color:Red] | O116: 涤纶-缎面布-切边-标准-64分-22码-Red | P116: 丝带\布料加工\涤纶布 | S116: 2024-05-14 05:50:43 +01:00
A117: 3DB-SJ14-1-0000068 | B117: X0020UILGL | C117: 3DB-SJ14-1-0000068 | D117: =_xlfn.XLOOKUP(C117,[1]单个产品!$A:$A,[1]单个产品!$F:$F) -> DL-RM-QB-BZ-32-022 | E117: B0CR3FTQNT | F117: =_xlfn.XLOOKUP(C117,[1]单个产品!$A:$A,[1]单个产品!$U:$U) -> 标准 | G117: 在售 | H117: B0CDP5VZ69 | I117: VATIN 4 Inch x 22Yards Wide Dark Green Satin Solid Ribbon Large Ribbon for Grand Opening Ribbon Cutting Ceremony Kit Chairs Pageant Sashes Table Hair Car Bows Gift Wrapping Party Festival Decoration | J117: VATIN-UK | K117: 英国 | L117: FBA | M117: VATIN | N117: [size:4" x 22 Yard];[color:Dark green] | O117: 涤纶-缎面布-切边-标准-32分-22码-Dk.Green | P117: 丝带\布料加工\涤纶布 | S117: 2024-05-10 22:32:29 +01:00
A118: 3DB-SJ14-2-0001876 | B118: X0020TLX2L | C118: 3DB-SJ14-2-0001876 | D118: =_xlfn.XLOOKUP(C118,[1]单个产品!$A:$A,[1]单个产品!$F:$F) -> LD-SZ-SM-BZ-02-050 | E118: B0CR3N6563 | F118: =_xlfn.XLOOKUP(C118,[1]单个产品!$A:$A,[1]单个产品!$U:$U) -> 标准 | G118: 在售 | H118: B0CDRRTTHC | I118: VATIN Double Faced Satin Ribbon 1/4 inch Navy Blue with Gold Edge Continuous 50 Yards for Decoration, Craft, Gift Wrappping Wedding Card Decoration | J118: VATIN-UK | K118: 英国 | L118: FBA | M118: VATIN | N118: [size:6mm X 45 Metres];[color:Navy/Gold] | O118: 涤纶带-特殊织边-双面织-标准-2分-50码-Navy & Gold | P118: 丝带\胚染\涤纶带 | S118: 2024-05-09 19:49:16 +01:00
A119: 3DB-SJ14-2-0001889 | B119: X0020RSD53 | C119: 3DB-SJ14-2-0001889 | D119: =_xlfn.XLOOKUP(C119,[1]单个产品!$A:$A,[1]单个产品!$F:$F) -> LD-SZ-SM-BZ-03-050 | E119: B0CR3TNB5X | F119: =_xlfn.XLOOKUP(C119,[1]单个产品!$A:$A,[1]单个产品!$U:$U) -> 标准 | G119: 在售 | H119: B0CDRRTTHC | I119: VATIN Double Faced Satin Ribbon 3/8 inch Navy with Gold Edge Continuous 50 Yards for Decoration, Craft, Gift Wrappping Wedding Card Decoration | J119: VATIN-UK | K119: 英国 | L119: FBA | M119: VATIN | N119: [size:10mm X 45 Metres];[color:Navy/Gold] | O119: 涤纶带-特殊织边-双面织-标准-3分-50码-Navy & Gold | P119: 丝带\胚染\涤纶带 | S119: 2024-05-08 05:33:07 +01:00
...
